[2023-09-23T22:54:40.196+0000] {taskinstance.py:1157} INFO - Dependencies all met for dep_context=non-requeueable deps ti=<TaskInstance: test_dag.test_model_api manual__2023-09-23T22:54:21.584635+00:00 [queued]>
[2023-09-23T22:54:40.206+0000] {taskinstance.py:1157} INFO - Dependencies all met for dep_context=requeueable deps ti=<TaskInstance: test_dag.test_model_api manual__2023-09-23T22:54:21.584635+00:00 [queued]>
[2023-09-23T22:54:40.207+0000] {taskinstance.py:1359} INFO - Starting attempt 1 of 1
[2023-09-23T22:54:40.227+0000] {taskinstance.py:1380} INFO - Executing <Task(_PythonDecoratedOperator): test_model_api> on 2023-09-23 22:54:21.584635+00:00
[2023-09-23T22:54:40.231+0000] {standard_task_runner.py:57} INFO - Started process 21 to run task
[2023-09-23T22:54:40.233+0000] {standard_task_runner.py:84} INFO - Running: ['airflow', 'tasks', 'run', 'test_dag', 'test_model_api', 'manual__2023-09-23T22:54:21.584635+00:00', '--job-id', '14', '--raw', '--subdir', 'DAGS_FOLDER/test_dag.py', '--cfg-path', '/tmp/tmpc3pc4z1x']
[2023-09-23T22:54:40.234+0000] {standard_task_runner.py:85} INFO - Job 14: Subtask test_model_api
[2023-09-23T22:54:40.256+0000] {logging_mixin.py:151} WARNING - /home/airflow/.local/lib/python3.8/site-packages/airflow/settings.py:195 DeprecationWarning: The sql_alchemy_conn option in [core] has been moved to the sql_alchemy_conn option in [database] - the old setting has been used, but please update your config.
[2023-09-23T22:54:40.289+0000] {task_command.py:415} INFO - Running <TaskInstance: test_dag.test_model_api manual__2023-09-23T22:54:21.584635+00:00 [running]> on host test-dag-test-model-api-ce416v9b
[2023-09-23T22:54:40.383+0000] {logging_mixin.py:151} WARNING - /home/airflow/.local/lib/python3.8/site-packages/airflow/providers/cncf/kubernetes/kube_config.py:57 DeprecationWarning: The namespace option in [kubernetes] has been moved to the namespace option in [kubernetes_executor] - the old setting has been used, but please update your config.
[2023-09-23T22:54:40.385+0000] {logging_mixin.py:151} WARNING - /home/airflow/.local/lib/python3.8/site-packages/airflow/providers/cncf/kubernetes/kube_config.py:71 DeprecationWarning: The namespace option in [kubernetes] has been moved to the namespace option in [kubernetes_executor] - the old setting has been used, but please update your config.
[2023-09-23T22:54:40.386+0000] {pod_generator.py:539} WARNING - Model file /opt/airflow/executor-pod-template.yml does not exist
[2023-09-23T22:54:40.542+0000] {taskinstance.py:1660} INFO - Exporting env vars: AIRFLOW_CTX_DAG_OWNER='airflow' AIRFLOW_CTX_DAG_ID='test_dag' AIRFLOW_CTX_TASK_ID='test_model_api' AIRFLOW_CTX_EXECUTION_DATE='2023-09-23T22:54:21.584635+00:00' AIRFLOW_CTX_TRY_NUMBER='1' AIRFLOW_CTX_DAG_RUN_ID='manual__2023-09-23T22:54:21.584635+00:00'
[2023-09-23T22:56:50.999+0000] {taskinstance.py:1935} ERROR - Task failed with exception
Traceback (most recent call last):
  File "/home/airflow/.local/lib/python3.8/site-packages/urllib3/connection.py", line 174, in _new_conn
    conn = connection.create_connection(
  File "/home/airflow/.local/lib/python3.8/site-packages/urllib3/util/connection.py", line 95, in create_connection
    raise err
  File "/home/airflow/.local/lib/python3.8/site-packages/urllib3/util/connection.py", line 85, in create_connection
    sock.connect(sa)
TimeoutError: [Errno 110] Connection timed out

During handling of the above exception, another exception occurred:

Traceback (most recent call last):
  File "/home/airflow/.local/lib/python3.8/site-packages/urllib3/connectionpool.py", line 714, in urlopen
    httplib_response = self._make_request(
  File "/home/airflow/.local/lib/python3.8/site-packages/urllib3/connectionpool.py", line 415, in _make_request
    conn.request(method, url, **httplib_request_kw)
  File "/home/airflow/.local/lib/python3.8/site-packages/urllib3/connection.py", line 244, in request
    super(HTTPConnection, self).request(method, url, body=body, headers=headers)
  File "/usr/local/lib/python3.8/http/client.py", line 1256, in request
    self._send_request(method, url, body, headers, encode_chunked)
  File "/usr/local/lib/python3.8/http/client.py", line 1302, in _send_request
    self.endheaders(body, encode_chunked=encode_chunked)
  File "/usr/local/lib/python3.8/http/client.py", line 1251, in endheaders
    self._send_output(message_body, encode_chunked=encode_chunked)
  File "/usr/local/lib/python3.8/http/client.py", line 1011, in _send_output
    self.send(msg)
  File "/usr/local/lib/python3.8/http/client.py", line 951, in send
    self.connect()
  File "/home/airflow/.local/lib/python3.8/site-packages/urllib3/connection.py", line 205, in connect
    conn = self._new_conn()
  File "/home/airflow/.local/lib/python3.8/site-packages/urllib3/connection.py", line 186, in _new_conn
    raise NewConnectionError(
urllib3.exceptions.NewConnectionError: <urllib3.connection.HTTPConnection object at 0x7fd6c397c310>: Failed to establish a new connection: [Errno 110] Connection timed out

During handling of the above exception, another exception occurred:

Traceback (most recent call last):
  File "/home/airflow/.local/lib/python3.8/site-packages/requests/adapters.py", line 486, in send
    resp = conn.urlopen(
  File "/home/airflow/.local/lib/python3.8/site-packages/urllib3/connectionpool.py", line 798, in urlopen
    retries = retries.increment(
  File "/home/airflow/.local/lib/python3.8/site-packages/urllib3/util/retry.py", line 592, in increment
    raise MaxRetryError(_pool, url, error or ResponseError(cause))
urllib3.exceptions.MaxRetryError: HTTPConnectionPool(host='c-predict.default.svc.cluster.local', port=80): Max retries exceeded with url: /v1/models/hourly (Caused by NewConnectionError('<urllib3.connection.HTTPConnection object at 0x7fd6c397c310>: Failed to establish a new connection: [Errno 110] Connection timed out'))

During handling of the above exception, another exception occurred:

Traceback (most recent call last):
  File "/home/airflow/.local/lib/python3.8/site-packages/airflow/decorators/base.py", line 221, in execute
    return_value = super().execute(context)
  File "/home/airflow/.local/lib/python3.8/site-packages/airflow/operators/python.py", line 192, in execute
    return_value = self.execute_callable()
  File "/home/airflow/.local/lib/python3.8/site-packages/airflow/operators/python.py", line 209, in execute_callable
    return self.python_callable(*self.op_args, **self.op_kwargs)
  File "/opt/airflow/dags/test_dag.py", line 38, in test_model_api
    res = requests.get(f"http://{host}/v1/models/hourly")
  File "/home/airflow/.local/lib/python3.8/site-packages/requests/api.py", line 73, in get
    return request("get", url, params=params, **kwargs)
  File "/home/airflow/.local/lib/python3.8/site-packages/requests/api.py", line 59, in request
    return session.request(method=method, url=url, **kwargs)
  File "/home/airflow/.local/lib/python3.8/site-packages/requests/sessions.py", line 589, in request
    resp = self.send(prep, **send_kwargs)
  File "/home/airflow/.local/lib/python3.8/site-packages/requests/sessions.py", line 703, in send
    r = adapter.send(request, **kwargs)
  File "/home/airflow/.local/lib/python3.8/site-packages/requests/adapters.py", line 519, in send
    raise ConnectionError(e, request=request)
requests.exceptions.ConnectionError: HTTPConnectionPool(host='c-predict.default.svc.cluster.local', port=80): Max retries exceeded with url: /v1/models/hourly (Caused by NewConnectionError('<urllib3.connection.HTTPConnection object at 0x7fd6c397c310>: Failed to establish a new connection: [Errno 110] Connection timed out'))
[2023-09-23T22:56:51.009+0000] {taskinstance.py:1398} INFO - Marking task as FAILED. dag_id=test_dag, task_id=test_model_api, execution_date=20230923T225421, start_date=20230923T225440, end_date=20230923T225651
[2023-09-23T22:56:51.026+0000] {standard_task_runner.py:104} ERROR - Failed to execute job 14 for task test_model_api (HTTPConnectionPool(host='c-predict.default.svc.cluster.local', port=80): Max retries exceeded with url: /v1/models/hourly (Caused by NewConnectionError('<urllib3.connection.HTTPConnection object at 0x7fd6c397c310>: Failed to establish a new connection: [Errno 110] Connection timed out')); 21)
[2023-09-23T22:56:51.068+0000] {local_task_job_runner.py:228} INFO - Task exited with return code 1
[2023-09-23T22:56:51.088+0000] {taskinstance.py:2776} INFO - 0 downstream tasks scheduled from follow-on schedule check
