[2023-09-20 11:02:42,622] {taskinstance.py:896} INFO - Dependencies all met for <TaskInstance: check_precision_dag.check_precision_task 2023-09-20T11:02:40.359133+00:00 [queued]>
[2023-09-20 11:02:42,632] {taskinstance.py:896} INFO - Dependencies all met for <TaskInstance: check_precision_dag.check_precision_task 2023-09-20T11:02:40.359133+00:00 [queued]>
[2023-09-20 11:02:42,632] {taskinstance.py:1087} INFO - 
--------------------------------------------------------------------------------
[2023-09-20 11:02:42,633] {taskinstance.py:1088} INFO - Starting attempt 1 of 1
[2023-09-20 11:02:42,633] {taskinstance.py:1089} INFO - 
--------------------------------------------------------------------------------
[2023-09-20 11:02:42,647] {taskinstance.py:1107} INFO - Executing <Task(PythonOperator): check_precision_task> on 2023-09-20T11:02:40.359133+00:00
[2023-09-20 11:02:42,651] {standard_task_runner.py:52} INFO - Started process 238 to run task
[2023-09-20 11:02:42,654] {standard_task_runner.py:76} INFO - Running: ['***', 'tasks', 'run', 'check_precision_dag', 'check_precision_task', '2023-09-20T11:02:40.359133+00:00', '--job-id', '27', '--pool', 'default_pool', '--raw', '--subdir', 'DAGS_FOLDER/check_precision_dag.py', '--cfg-path', '/tmp/tmpy4gvscvh', '--error-file', '/tmp/tmpzvjlebiy']
[2023-09-20 11:02:42,655] {standard_task_runner.py:77} INFO - Job 27: Subtask check_precision_task
[2023-09-20 11:02:42,692] {logging_mixin.py:104} INFO - Running <TaskInstance: check_precision_dag.check_precision_task 2023-09-20T11:02:40.359133+00:00 [running]> on host 71aa876fba23
[2023-09-20 11:02:42,734] {taskinstance.py:1302} INFO - Exporting the following env vars:
AIRFLOW_CTX_DAG_OWNER=***
AIRFLOW_CTX_DAG_ID=check_precision_dag
AIRFLOW_CTX_TASK_ID=check_precision_task
AIRFLOW_CTX_EXECUTION_DATE=2023-09-20T11:02:40.359133+00:00
AIRFLOW_CTX_DAG_RUN_ID=manual__2023-09-20T11:02:40.359133+00:00
[2023-09-20 11:02:42,737] {taskinstance.py:1501} ERROR - Task failed with exception
Traceback (most recent call last):
  File "/home/airflow/.local/lib/python3.6/site-packages/mysql/connector/connection_cext.py", line 233, in _open_connection
    self._cmysql.connect(**cnx_kwargs)
_mysql_connector.MySQLInterfaceError: Can't connect to MySQL server on 'localhost' (99)

During handling of the above exception, another exception occurred:

Traceback (most recent call last):
  File "/home/airflow/.local/lib/python3.6/site-packages/airflow/models/taskinstance.py", line 1157, in _run_raw_task
    self._prepare_and_execute_task_with_callbacks(context, task)
  File "/home/airflow/.local/lib/python3.6/site-packages/airflow/models/taskinstance.py", line 1331, in _prepare_and_execute_task_with_callbacks
    result = self._execute_task(context, task_copy)
  File "/home/airflow/.local/lib/python3.6/site-packages/airflow/models/taskinstance.py", line 1361, in _execute_task
    result = task_copy.execute(context=context)
  File "/home/airflow/.local/lib/python3.6/site-packages/airflow/operators/python.py", line 150, in execute
    return_value = self.execute_callable()
  File "/home/airflow/.local/lib/python3.6/site-packages/airflow/operators/python.py", line 161, in execute_callable
    return self.python_callable(*self.op_args, **self.op_kwargs)
  File "/opt/airflow/dags/check_precision_dag.py", line 50, in get_result
    df_klines = sql_to_df(klin_conn, 'klines')
  File "/opt/airflow/dags/check_precision_dag.py", line 40, in sql_to_df
    connexion = mysql.connector.connect(**connector)
  File "/home/airflow/.local/lib/python3.6/site-packages/mysql/connector/__init__.py", line 270, in connect
    return CMySQLConnection(*args, **kwargs)
  File "/home/airflow/.local/lib/python3.6/site-packages/mysql/connector/connection_cext.py", line 86, in __init__
    self.connect(**kwargs)
  File "/home/airflow/.local/lib/python3.6/site-packages/mysql/connector/abstracts.py", line 985, in connect
    self._open_connection()
  File "/home/airflow/.local/lib/python3.6/site-packages/mysql/connector/connection_cext.py", line 236, in _open_connection
    sqlstate=exc.sqlstate)
mysql.connector.errors.DatabaseError: 2003 (HY000): Can't connect to MySQL server on 'localhost' (99)
[2023-09-20 11:02:42,743] {taskinstance.py:1551} INFO - Marking task as FAILED. dag_id=check_precision_dag, task_id=check_precision_task, execution_date=20230920T110240, start_date=20230920T110242, end_date=20230920T110242
[2023-09-20 11:02:42,786] {local_task_job.py:151} INFO - Task exited with return code 1
